Workbook

Sheet ESTADO_CUENTA
C3: ESTADO DE CUENTA · COMPRADOR
C6: ID VENTA | D6: V010
C8: Comprador | D8: =IFERROR(INDEX(VENTAS!$E$2:$E$100,MATCH($D$6,VENTAS!$A$2:$A$100,0)),"") -> 0 | F8: Valor negocio | G8: =IFERROR(INDEX(VENTAS!$K$2:$K$100,MATCH($D$6,VENTAS!$A$2:$A$100,0)),0) -> 0
C9: Proyecto | D9: =IFERROR(INDEX(PROYECTOS!$B$2:$B$100,MATCH(INDEX(VENTAS!$B$2:$B$100,MATCH($D$6,VENTAS!$A$2:$A$100,0)),PROYECTOS!$A$2:$A$100,0)),"") -> Amaranta | F9: Total recibido | G9: =SUMIF(ABONOS!$B$2:$B$220,$D$6,ABONOS!$E$2:$E$220) -> 0
C10: Lote | D10: =IFERROR(INDEX(VENTAS!$C$2:$C$100,MATCH($D$6,VENTAS!$A$2:$A$100,0)),"") -> L-010 | F10: Saldo pendiente | G10: =G8-G9 -> 0
C11: Documento | D11: =IFERROR(INDEX(VENTAS!$F$2:$F$100,MATCH($D$6,VENTAS!$A$2:$A$100,0)),"") -> 0 | F11: % recaudado | G11: =IFERROR(G9/G8,0) -> 0
C12: Fecha venta | D12: =IFERROR(INDEX(VENTAS!$J$2:$J$100,MATCH($D$6,VENTAS!$A$2:$A$100,0)),"") -> 0 | F12: Inicial pactada | G12: =IFERROR(INDEX(VENTAS!$L$2:$L$100,MATCH($D$6,VENTAS!$A$2:$A$100,0)),0) -> 0
C15: N° abono | D15: Fecha | E15: Valor recibido | F15: Medio de pago | G15: Referencia
C16: =IFERROR(INDEX(ABONOS!$C$2:$C$220,IFERROR(_xlfn.AGGREGATE(15,6,(ROW(ABONOS!$B$2:$B$220)-ROW(ABONOS!$B$2)+1)/(ABONOS!$B$2:$B$220=$D$6),ROWS($C$16:C16)),"")),"") | D16: =IF($C16="","",IFERROR(INDEX(ABONOS!$D$2:$D$220,IFERROR(_xlfn.AGGREGATE(15,6,(ROW(ABONOS!$B$2:$B$220)-ROW(ABONOS!$B$2)+1)/(ABONOS!$B$2:$B$220=$D$6),ROWS($C$16:C16)),"")),"")) | E16: =IF($C16="","",IFERROR(INDEX(ABONOS!$E$2:$E$220,IFERROR(_xlfn.AGGREGATE(15,6,(ROW(ABONOS!$B$2:$B$220)-ROW(ABONOS!$B$2)+1)/(ABONOS!$B$2:$B$220=$D$6),ROWS($C$16:C16)),"")),"")) | F16: =IF($C16="","",IFERROR(INDEX(ABONOS!$F$2:$F$220,IFERROR(_xlfn.AGGREGATE(15,6,(ROW(ABONOS!$B$2:$B$220)-ROW(ABONOS!$B$2)+1)/(ABONOS!$B$2:$B$220=$D$6),ROWS($C$16:C16)),"")),"")) | G16: =IF($C16="","",IFERROR(INDEX(ABONOS!$G$2:$G$220,IFERROR(_xlfn.AGGREGATE(15,6,(ROW(ABONOS!$B$2:$B$220)-ROW(ABONOS!$B$2)+1)/(ABONOS!$B$2:$B$220=$D$6),ROWS($C$16:C16)),"")),""))
C17: =IFERROR(INDEX(ABONOS!$C$2:$C$220,IFERROR(_xlfn.AGGREGATE(15,6,(ROW(ABONOS!$B$2:$B$220)-ROW(ABONOS!$B$2)+1)/(ABONOS!$B$2:$B$220=$D$6),ROWS($C$16:C17)),"")),"") | D17: =IF($C17="","",IFERROR(INDEX(ABONOS!$D$2:$D$220,IFERROR(_xlfn.AGGREGATE(15,6,(ROW(ABONOS!$B$2:$B$220)-ROW(ABONOS!$B$2)+1)/(ABONOS!$B$2:$B$220=$D$6),ROWS($C$16:C17)),"")),"")) | E17: =IF($C17="","",IFERROR(INDEX(ABONOS!$E$2:$E$220,IFERROR(_xlfn.AGGREGATE(15,6,(ROW(ABONOS!$B$2:$B$220)-ROW(ABONOS!$B$2)+1)/(ABONOS!$B$2:$B$220=$D$6),ROWS($C$16:C17)),"")),"")) | F17: =IF($C17="","",IFERROR(INDEX(ABONOS!$F$2:$F$220,IFERROR(_xlfn.AGGREGATE(15,6,(ROW(ABONOS!$B$2:$B$220)-ROW(ABONOS!$B$2)+1)/(ABONOS!$B$2:$B$220=$D$6),ROWS($C$16:C17)),"")),"")) | G17: =IF($C17="","",IFERROR(INDEX(ABONOS!$G$2:$G$220,IFERROR(_xlfn.AGGREGATE(15,6,(ROW(ABONOS!$B$2:$B$220)-ROW(ABONOS!$B$2)+1)/(ABONOS!$B$2:$B$220=$D$6),ROWS($C$16:C17)),"")),""))
C18: =IFERROR(INDEX(ABONOS!$C$2:$C$220,IFERROR(_xlfn.AGGREGATE(15,6,(ROW(ABONOS!$B$2:$B$220)-ROW(ABONOS!$B$2)+1)/(ABONOS!$B$2:$B$220=$D$6),ROWS($C$16:C18)),"")),"") | D18: =IF($C18="","",IFERROR(INDEX(ABONOS!$D$2:$D$220,IFERROR(_xlfn.AGGREGATE(15,6,(ROW(ABONOS!$B$2:$B$220)-ROW(ABONOS!$B$2)+1)/(ABONOS!$B$2:$B$220=$D$6),ROWS($C$16:C18)),"")),"")) | E18: =IF($C18="","",IFERROR(INDEX(ABONOS!$E$2:$E$220,IFERROR(_xlfn.AGGREGATE(15,6,(ROW(ABONOS!$B$2:$B$220)-ROW(ABONOS!$B$2)+1)/(ABONOS!$B$2:$B$220=$D$6),ROWS($C$16:C18)),"")),"")) | F18: =IF($C18="","",IFERROR(INDEX(ABONOS!$F$2:$F$220,IFERROR(_xlfn.AGGREGATE(15,6,(ROW(ABONOS!$B$2:$B$220)-ROW(ABONOS!$B$2)+1)/(ABONOS!$B$2:$B$220=$D$6),ROWS($C$16:C18)),"")),"")) | G18: =IF($C18="","",IFERROR(INDEX(ABONOS!$G$2:$G$220,IFERROR(_xlfn.AGGREGATE(15,6,(ROW(ABONOS!$B$2:$B$220)-ROW(ABONOS!$B$2)+1)/(ABONOS!$B$2:$B$220=$D$6),ROWS($C$16:C18)),"")),""))
C19: =IFERROR(INDEX(ABONOS!$C$2:$C$220,IFERROR(_xlfn.AGGREGATE(15,6,(ROW(ABONOS!$B$2:$B$220)-ROW(ABONOS!$B$2)+1)/(ABONOS!$B$2:$B$220=$D$6),ROWS($C$16:C19)),"")),"") | D19: =IF($C19="","",IFERROR(INDEX(ABONOS!$D$2:$D$220,IFERROR(_xlfn.AGGREGATE(15,6,(ROW(ABONOS!$B$2:$B$220)-ROW(ABONOS!$B$2)+1)/(ABONOS!$B$2:$B$220=$D$6),ROWS($C$16:C19)),"")),"")) | E19: =IF($C19="","",IFERROR(INDEX(ABONOS!$E$2:$E$220,IFERROR(_xlfn.AGGREGATE(15,6,(ROW(ABONOS!$B$2:$B$220)-ROW(ABONOS!$B$2)+1)/(ABONOS!$B$2:$B$220=$D$6),ROWS($C$16:C19)),"")),"")) | F19: =IF($C19="","",IFERROR(INDEX(ABONOS!$F$2:$F$220,IFERROR(_xlfn.AGGREGATE(15,6,(ROW(ABONOS!$B$2:$B$220)-ROW(ABONOS!$B$2)+1)/(ABONOS!$B$2:$B$220=$D$6),ROWS($C$16:C19)),"")),"")) | G19: =IF($C19="","",IFERROR(INDEX(ABONOS!$G$2:$G$220,IFERROR(_xlfn.AGGREGATE(15,6,(ROW(ABONOS!$B$2:$B$220)-ROW(ABONOS!$B$2)+1)/(ABONOS!$B$2:$B$220=$D$6),ROWS($C$16:C19)),"")),""))
C20: =IFERROR(INDEX(ABONOS!$C$2:$C$220,IFERROR(_xlfn.AGGREGATE(15,6,(ROW(ABONOS!$B$2:$B$220)-ROW(ABONOS!$B$2)+1)/(ABONOS!$B$2:$B$220=$D$6),ROWS($C$16:C20)),"")),"") | D20: =IF($C20="","",IFERROR(INDEX(ABONOS!$D$2:$D$220,IFERROR(_xlfn.AGGREGATE(15,6,(ROW(ABONOS!$B$2:$B$220)-ROW(ABONOS!$B$2)+1)/(ABONOS!$B$2:$B$220=$D$6),ROWS($C$16:C20)),"")),"")) | E20: =IF($C20="","",IFERROR(INDEX(ABONOS!$E$2:$E$220,IFERROR(_xlfn.AGGREGATE(15,6,(ROW(ABONOS!$B$2:$B$220)-ROW(ABONOS!$B$2)+1)/(ABONOS!$B$2:$B$220=$D$6),ROWS($C$16:C20)),"")),"")) | F20: =IF($C20="","",IFERROR(INDEX(ABONOS!$F$2:$F$220,IFERROR(_xlfn.AGGREGATE(15,6,(ROW(ABONOS!$B$2:$B$220)-ROW(ABONOS!$B$2)+1)/(ABONOS!$B$2:$B$220=$D$6),ROWS($C$16:C20)),"")),"")) | G20: =IF($C20="","",IFERROR(INDEX(ABONOS!$G$2:$G$220,IFERROR(_xlfn.AGGREGATE(15,6,(ROW(ABONOS!$B$2:$B$220)-ROW(ABONOS!$B$2)+1)/(ABONOS!$B$2:$B$220=$D$6),ROWS($C$16:C20)),"")),""))
C21: =IFERROR(INDEX(ABONOS!$C$2:$C$220,IFERROR(_xlfn.AGGREGATE(15,6,(ROW(ABONOS!$B$2:$B$220)-ROW(ABONOS!$B$2)+1)/(ABONOS!$B$2:$B$220=$D$6),ROWS($C$16:C21)),"")),"") | D21: =IF($C21="","",IFERROR(INDEX(ABONOS!$D$2:$D$220,IFERROR(_xlfn.AGGREGATE(15,6,(ROW(ABONOS!$B$2:$B$220)-ROW(ABONOS!$B$2)+1)/(ABONOS!$B$2:$B$220=$D$6),ROWS($C$16:C21)),"")),"")) | E21: =IF($C21="","",IFERROR(INDEX(ABONOS!$E$2:$E$220,IFERROR(_xlfn.AGGREGATE(15,6,(ROW(ABONOS!$B$2:$B$220)-ROW(ABONOS!$B$2)+1)/(ABONOS!$B$2:$B$220=$D$6),ROWS($C$16:C21)),"")),"")) | F21: =IF($C21="","",IFERROR(INDEX(ABONOS!$F$2:$F$220,IFERROR(_xlfn.AGGREGATE(15,6,(ROW(ABONOS!$B$2:$B$220)-ROW(ABONOS!$B$2)+1)/(ABONOS!$B$2:$B$220=$D$6),ROWS($C$16:C21)),"")),"")) | G21: =IF($C21="","",IFERROR(INDEX(ABONOS!$G$2:$G$220,IFERROR(_xlfn.AGGREGATE(15,6,(ROW(ABONOS!$B$2:$B$220)-ROW(ABONOS!$B$2)+1)/(ABONOS!$B$2:$B$220=$D$6),ROWS($C$16:C21)),"")),""))
C22: =IFERROR(INDEX(ABONOS!$C$2:$C$220,IFERROR(_xlfn.AGGREGATE(15,6,(ROW(ABONOS!$B$2:$B$220)-ROW(ABONOS!$B$2)+1)/(ABONOS!$B$2:$B$220=$D$6),ROWS($C$16:C22)),"")),"") | D22: =IF($C22="","",IFERROR(INDEX(ABONOS!$D$2:$D$220,IFERROR(_xlfn.AGGREGATE(15,6,(ROW(ABONOS!$B$2:$B$220)-ROW(ABONOS!$B$2)+1)/(ABONOS!$B$2:$B$220=$D$6),ROWS($C$16:C22)),"")),"")) | E22: =IF($C22="","",IFERROR(INDEX(ABONOS!$E$2:$E$220,IFERROR(_xlfn.AGGREGATE(15,6,(ROW(ABONOS!$B$2:$B$220)-ROW(ABONOS!$B$2)+1)/(ABONOS!$B$2:$B$220=$D$6),ROWS($C$16:C22)),"")),"")) | F22: =IF($C22="","",IFERROR(INDEX(ABONOS!$F$2:$F$220,IFERROR(_xlfn.AGGREGATE(15,6,(ROW(ABONOS!$B$2:$B$220)-ROW(ABONOS!$B$2)+1)/(ABONOS!$B$2:$B$220=$D$6),ROWS($C$16:C22)),"")),"")) | G22: =IF($C22="","",IFERROR(INDEX(ABONOS!$G$2:$G$220,IFERROR(_xlfn.AGGREGATE(15,6,(ROW(ABONOS!$B$2:$B$220)-ROW(ABONOS!$B$2)+1)/(ABONOS!$B$2:$B$220=$D$6),ROWS($C$16:C22)),"")),""))
C23: =IFERROR(INDEX(ABONOS!$C$2:$C$220,IFERROR(_xlfn.AGGREGATE(15,6,(ROW(ABONOS!$B$2:$B$220)-ROW(ABONOS!$B$2)+1)/(ABONOS!$B$2:$B$220=$D$6),ROWS($C$16:C23)),"")),"") | D23: =IF($C23="","",IFERROR(INDEX(ABONOS!$D$2:$D$220,IFERROR(_xlfn.AGGREGATE(15,6,(ROW(ABONOS!$B$2:$B$220)-ROW(ABONOS!$B$2)+1)/(ABONOS!$B$2:$B$220=$D$6),ROWS($C$16:C23)),"")),"")) | E23: =IF($C23="","",IFERROR(INDEX(ABONOS!$E$2:$E$220,IFERROR(_xlfn.AGGREGATE(15,6,(ROW(ABONOS!$B$2:$B$220)-ROW(ABONOS!$B$2)+1)/(ABONOS!$B$2:$B$220=$D$6),ROWS($C$16:C23)),"")),"")) | F23: =IF($C23="","",IFERROR(INDEX(ABONOS!$F$2:$F$220,IFERROR(_xlfn.AGGREGATE(15,6,(ROW(ABONOS!$B$2:$B$220)-ROW(ABONOS!$B$2)+1)/(ABONOS!$B$2:$B$220=$D$6),ROWS($C$16:C23)),"")),"")) | G23: =IF($C23="","",IFERROR(INDEX(ABONOS!$G$2:$G$220,IFERROR(_xlfn.AGGREGATE(15,6,(ROW(ABONOS!$B$2:$B$220)-ROW(ABONOS!$B$2)+1)/(ABONOS!$B$2:$B$220=$D$6),ROWS($C$16:C23)),"")),""))
C24: =IFERROR(INDEX(ABONOS!$C$2:$C$220,IFERROR(_xlfn.AGGREGATE(15,6,(ROW(ABONOS!$B$2:$B$220)-ROW(ABONOS!$B$2)+1)/(ABONOS!$B$2:$B$220=$D$6),ROWS($C$16:C24)),"")),"") | D24: =IF($C24="","",IFERROR(INDEX(ABONOS!$D$2:$D$220,IFERROR(_xlfn.AGGREGATE(15,6,(ROW(ABONOS!$B$2:$B$220)-ROW(ABONOS!$B$2)+1)/(ABONOS!$B$2:$B$220=$D$6),ROWS($C$16:C24)),"")),"")) | E24: =IF($C24="","",IFERROR(INDEX(ABONOS!$E$2:$E$220,IFERROR(_xlfn.AGGREGATE(15,6,(ROW(ABONOS!$B$2:$B$220)-ROW(ABONOS!$B$2)+1)/(ABONOS!$B$2:$B$220=$D$6),ROWS($C$16:C24)),"")),"")) | F24: =IF($C24="","",IFERROR(INDEX(ABONOS!$F$2:$F$220,IFERROR(_xlfn.AGGREGATE(15,6,(ROW(ABONOS!$B$2:$B$220)-ROW(ABONOS!$B$2)+1)/(ABONOS!$B$2:$B$220=$D$6),ROWS($C$16:C24)),"")),"")) | G24: =IF($C24="","",IFERROR(INDEX(ABONOS!$G$2:$G$220,IFERROR(_xlfn.AGGREGATE(15,6,(ROW(ABONOS!$B$2:$B$220)-ROW(ABONOS!$B$2)+1)/(ABONOS!$B$2:$B$220=$D$6),ROWS($C$16:C24)),"")),""))
C25: =IFERROR(INDEX(ABONOS!$C$2:$C$220,IFERROR(_xlfn.AGGREGATE(15,6,(ROW(ABONOS!$B$2:$B$220)-ROW(ABONOS!$B$2)+1)/(ABONOS!$B$2:$B$220=$D$6),ROWS($C$16:C25)),"")),"") | D25: =IF($C25="","",IFERROR(INDEX(ABONOS!$D$2:$D$220,IFERROR(_xlfn.AGGREGATE(15,6,(ROW(ABONOS!$B$2:$B$220)-ROW(ABONOS!$B$2)+1)/(ABONOS!$B$2:$B$220=$D$6),ROWS($C$16:C25)),"")),"")) | E25: =IF($C25="","",IFERROR(INDEX(ABONOS!$E$2:$E$220,IFERROR(_xlfn.AGGREGATE(15,6,(ROW(ABONOS!$B$2:$B$220)-ROW(ABONOS!$B$2)+1)/(ABONOS!$B$2:$B$220=$D$6),ROWS($C$16:C25)),"")),"")) | F25: =IF($C25="","",IFERROR(INDEX(ABONOS!$F$2:$F$220,IFERROR(_xlfn.AGGREGATE(15,6,(ROW(ABONOS!$B$2:$B$220)-ROW(ABONOS!$B$2)+1)/(ABONOS!$B$2:$B$220=$D$6),ROWS($C$16:C25)),"")),"")) | G25: =IF($C25="","",IFERROR(INDEX(ABONOS!$G$2:$G$220,IFERROR(_xlfn.AGGREGATE(15,6,(ROW(ABONOS!$B$2:$B$220)-ROW(ABONOS!$B$2)+1)/(ABONOS!$B$2:$B$220=$D$6),ROWS($C$16:C25)),"")),""))
C26: =IFERROR(INDEX(ABONOS!$C$2:$C$220,IFERROR(_xlfn.AGGREGATE(15,6,(ROW(ABONOS!$B$2:$B$220)-ROW(ABONOS!$B$2)+1)/(ABONOS!$B$2:$B$220=$D$6),ROWS($C$16:C26)),"")),"") | D26: =IF($C26="","",IFERROR(INDEX(ABONOS!$D$2:$D$220,IFERROR(_xlfn.AGGREGATE(15,6,(ROW(ABONOS!$B$2:$B$220)-ROW(ABONOS!$B$2)+1)/(ABONOS!$B$2:$B$220=$D$6),ROWS($C$16:C26)),"")),"")) | E26: =IF($C26="","",IFERROR(INDEX(ABONOS!$E$2:$E$220,IFERROR(_xlfn.AGGREGATE(15,6,(ROW(ABONOS!$B$2:$B$220)-ROW(ABONOS!$B$2)+1)/(ABONOS!$B$2:$B$220=$D$6),ROWS($C$16:C26)),"")),"")) | F26: =IF($C26="","",IFERROR(INDEX(ABONOS!$F$2:$F$220,IFERROR(_xlfn.AGGREGATE(15,6,(ROW(ABONOS!$B$2:$B$220)-ROW(ABONOS!$B$2)+1)/(ABONOS!$B$2:$B$220=$D$6),ROWS($C$16:C26)),"")),"")) | G26: =IF($C26="","",IFERROR(INDEX(ABONOS!$G$2:$G$220,IFERROR(_xlfn.AGGREGATE(15,6,(ROW(ABONOS!$B$2:$B$220)-ROW(ABONOS!$B$2)+1)/(ABONOS!$B$2:$B$220=$D$6),ROWS($C$16:C26)),"")),""))
C27: =IFERROR(INDEX(#REF!,IFERROR(_xlfn.AGGREGATE(15,6,(ROW(#REF!)-ROW(#REF!)+1)/(#REF!=$D$6),ROWS($C$27:C27)),"")),"") | D27: =IFERROR(INDEX(#REF!,IFERROR(_xlfn.AGGREGATE(15,6,(ROW(#REF!)-ROW(#REF!)+1)/(#REF!=$D$6),ROWS($C$27:C27)),"")),"") | E27: =IFERROR(INDEX(#REF!,IFERROR(_xlfn.AGGREGATE(15,6,(ROW(#REF!)-ROW(#REF!)+1)/(#REF!=$D$6),ROWS($C$27:C27)),"")),"") | F27: =IFERROR(INDEX(#REF!,IFERROR(_xlfn.AGGREGATE(15,6,(ROW(#REF!)-ROW(#REF!)+1)/(#REF!=$D$6),ROWS($C$27:C27)),"")),"") | G27: =IFERROR(INDEX(#REF!,IFERROR(_xlfn.AGGREGATE(15,6,(ROW(#REF!)-ROW(#REF!)+1)/(#REF!=$D$6),ROWS($C$27:C27)),"")),"") | H27: =IFERROR(INDEX(#REF!,IFERROR(_xlfn.AGGREGATE(15,6,(ROW(#REF!)-ROW(#REF!)+1)/(#REF!=$D$6),ROWS($C$27:C27)),"")),"")

Sheet VENTAS
A1: ID venta | B1: ID proyecto | C1: Lote | D1: Área m² | E1: Comprador | F1: Cédula | G1: Teléfono | H1: Correo | I1: Dirección | J1: Fecha venta | K1: Valor negocio | L1: Inicial pactada | M1: Método inicial | N1: Banco | O1: Observación | P1: Total abonado | Q1: Saldo negocio | R1: % recaudado
A2: V001 | B2: Ama | C2: L-001 | D2: 350 | P2: =IF(A2="","",SUMIF(ABONOS!$B$2:$B$220,A2,ABONOS!$E$2:$E$220)) -> 0 | Q2: =IF(A2="","",K2-P2) -> 0 | R2: =IFERROR(IF(A2="","",P2/K2),"")
A3: V002 | B3: Ama | C3: L-002 | D3: 656 | P3: =IF(A3="","",SUMIF(ABONOS!$B$2:$B$220,A3,ABONOS!$E$2:$E$220)) -> 0 | Q3: =IF(A3="","",K3-P3) -> 0 | R3: =IFERROR(IF(A3="","",P3/K3),"")
A4: V003 | B4: Ama | C4: L-003 | D4: 281 | E4: JAVIER GARCIA | F4: 16862434 | G4: 3174211264 | H4: yavierhjg@hotmail.com | I4: Calle 5 #3-73 Santa Elena | J4: 46253 | K4: 48891941 | L4: 24446016 | P4: =IF(A4="","",SUMIF(ABONOS!$B$2:$B$220,A4,ABONOS!$E$2:$E$220)) -> 30000000 | Q4: =IF(A4="","",K4-P4) -> 18891941 | R4: =IFERROR(IF(A4="","",P4/K4),"") -> 0.61359806
A5: V004 | B5: Ama | C5: L-004 | D5: 251 | E5: JAVIER GARCIA | F5: 16862434 | G5: 3174211264 | H5: yavierhjg@hotmail.com | I5: Calle 5 #3-73 Santa Elena | J5: 46253 | K5: 43672161 | L5: 21836080 | P5: =IF(A5="","",SUMIF(ABONOS!$B$2:$B$220,A5,ABONOS!$E$2:$E$220)) -> 30000000 | Q5: =IF(A5="","",K5-P5) -> 13672161 | R5: =IFERROR(IF(A5="","",P5/K5),"") -> 0.68693647
A6: V005 | B6: Ama | C6: L-005 | D6: 251 | P6: =IF(A6="","",SUMIF(ABONOS!$B$2:$B$220,A6,ABONOS!$E$2:$E$220)) -> 0 | Q6: =IF(A6="","",K6-P6) -> 0 | R6: =IFERROR(IF(A6="","",P6/K6),"")
A7: V006 | B7: Ama | C7: L-006 | D7: 251 | E7: SANTIAGO CORREA CAMPAÑA | F7: 1007888222 | G7: 3013555173 | H7: sacorreaca@unal.edu.co | I7: Calle 8 #12-26 Pradera | K7: 65129741 | L7: 32564870 | M7: Consignacion | N7: Davivienda | O7: No tiene promesa | P7: =IF(A7="","",SUMIF(ABONOS!$B$2:$B$220,A7,ABONOS!$E$2:$E$220)) -> 18500000 | Q7: =IF(A7="","",K7-P7) -> 46629741 | R7: =IFERROR(IF(A7="","",P7/K7),"") -> 0.28404842
A8: V007 | B8: Ama | C8: L-007 | D8: 250 | E8: SANTIAGO CORREA CAMPAÑA | F8: 1007888222 | G8: 3013555173 | H8: sacorreaca@unal.edu.co | I8: Calle 8 #12-26 Pradera | K8: 64870259 | L8: 32435129 | M8: Consignacion | N8: Davivienda | O8: No tiene promesa | P8: =IF(A8="","",SUMIF(ABONOS!$B$2:$B$220,A8,ABONOS!$E$2:$E$220)) -> 18500000 | Q8: =IF(A8="","",K8-P8) -> 46370259 | R8: =IFERROR(IF(A8="","",P8/K8),"") -> 0.28518462
A9: V008 | B9: Ama | C9: L-008 | D9: 251 | E9: JUAN JOSE RAMIREZ SALAZAR | F9: 1114835068 | J9: 46280 | K9: 90000000 | L9: 45000000 | P9: =IF(A9="","",SUMIF(ABONOS!$B$2:$B$220,A9,ABONOS!$E$2:$E$220)) -> 45000000 | Q9: =IF(A9="","",K9-P9) -> 45000000 | R9: =IFERROR(IF(A9="","",P9/K9),"") -> 0.5
A10: V009 | B10: Ama | C10: L-009 | D10: 252 | P10: =IF(A10="","",SUMIF(ABONOS!$B$2:$B$220,A10,ABONOS!$E$2:$E$220)) -> 0 | Q10: =IF(A10="","",K10-P10) -> 0 | R10: =IFERROR(IF(A10="","",P10/K10),"")
A11: V010 | B11: Ama | C11: L-010 | D11: 253 | P11: =IF(A11="","",SUMIF(ABONOS!$B$2:$B$220,A11,ABONOS!$E$2:$E$220)) -> 0 | Q11: =IF(A11="","",K11-P11) -> 0 | R11: =IFERROR(IF(A11="","",P11/K11),"")
A12: V011 | B12: Ama | C12: L-011 | D12: 255 | P12: =IF(A12="","",SUMIF(ABONOS!$B$2:$B$220,A12,ABONOS!$E$2:$E$220)) -> 0 | Q12: =IF(A12="","",K12-P12) -> 0 | R12: =IFERROR(IF(A12="","",P12/K12),"")
A13: V012 | B13: Ama | C13: L-012 | D13: 256 | E13: DANIELA GUTIERREZ | F13: 1007837072 | G13: 3116774637 | H13: linethdanielagv@hotmail.com | I13: Calle 6 #2-06 Amaime | K13: 59534884 | L13: 29767442 | M13: Efectivo | O13: No tiene promesa | P13: =IF(A13="","",SUMIF(ABONOS!$B$2:$B$220,A13,ABONOS!$E$2:$E$220)) -> 0 | Q13: =IF(A13="","",K13-P13) -> 59534884 | R13: =IFERROR(IF(A13="","",P13/K13),"") -> 0
A14: V013 | B14: Ama | C14: L-013 | D14: 260 | E14: DANIELA GUTIERREZ | F14: 1007837072 | G14: 3116774637 | H14: linethdanielagv@hotmail.com | I14: Calle 6 #2-06 Amaime | K14: 60465116 | L14: 30232558 | M14: Efectivo | O14: No tiene promesa | P14: =IF(A14="","",SUMIF(ABONOS!$B$2:$B$220,A14,ABONOS!$E$2:$E$220)) -> 0 | Q14: =IF(A14="","",K14-P14) -> 60465116 | R14: =IFERROR(IF(A14="","",P14/K14),"") -> 0
A15: V014 | B15: Ama | C15: L-014 | D15: 260 | P15: =IF(A15="","",SUMIF(ABONOS!$B$2:$B$220,A15,ABONOS!$E$2:$E$220)) -> 0 | Q15: =IF(A15="","",K15-P15) -> 0 | R15: =IFERROR(IF(A15="","",P15/K15),"")
A16: V015 | B16: Ama | C16: L-015 | D16: 260 | P16: =IF(A16="","",SUMIF(ABONOS!$B$2:$B$220,A16,ABONOS!$E$2:$E$220)) -> 0 | Q16: =IF(A16="","",K16-P16) -> 0 | R16: =IFERROR(IF(A16="","",P16/K16),"")
A17: V016 | B17: Ama | C17: L-016 | D17: 260 | P17: =IF(A17="","",SUMIF(ABONOS!$B$2:$B$220,A17,ABONOS!$E$2:$E$220)) -> 0 | Q17: =IF(A17="","",K17-P17) -> 0 | R17: =IFERROR(IF(A17="","",P17/K17),"")
A18: V017 | B18: Ama | C18: L-017 | D18: 258 | P18: =IF(A18="","",SUMIF(ABONOS!$B$2:$B$220,A18,ABONOS!$E$2:$E$220)) -> 0 | Q18: =IF(A18="","",K18-P18) -> 0 | R18: =IFERROR(IF(A18="","",P18/K18),"")
A19: V018 | B19: Ama | C19: L-018 | D19: 256 | P19: =IF(A19="","",SUMIF(ABONOS!$B$2:$B$220,A19,ABONOS!$E$2:$E$220)) -> 0 | Q19: =IF(A19="","",K19-P19) -> 0 | R19: =IFERROR(IF(A19="","",P19/K19),"")
A20: V019 | B20: Ama | C20: L-019 | D20: 254 | P20: =IF(A20="","",SUMIF(ABONOS!$B$2:$B$220,A20,ABONOS!$E$2:$E$220)) -> 0 | Q20: =IF(A20="","",K20-P20) -> 0 | R20: =IFERROR(IF(A20="","",P20/K20),"")
A21: V020 | B21: Ama | C21: L-020 | D21: 510 | P21: =IF(A21="","",SUMIF(ABONOS!$B$2:$B$220,A21,ABONOS!$E$2:$E$220)) -> 0 | Q21: =IF(A21="","",K21-P21) -> 0 | R21: =IFERROR(IF(A21="","",P21/K21),"")
A22: V021 | B22: Ama | C22: L-021 | D22: 475 | P22: =IF(A22="","",SUMIF(ABONOS!$B$2:$B$220,A22,ABONOS!$E$2:$E$220)) -> 0 | Q22: =IF(A22="","",K22-P22) -> 0 | R22: =IFERROR(IF(A22="","",P22/K22),"")
A23: V022 | B23: Ama | C23: L-022 | D23: 250 | P23: =IF(A23="","",SUMIF(ABONOS!$B$2:$B$220,A23,ABONOS!$E$2:$E$220)) -> 0 | Q23: =IF(A23="","",K23-P23) -> 0 | R23: =IFERROR(IF(A23="","",P23/K23),"")
A24: V023 | B24: Ama | C24: L-023 | D24: 250 | P24: =IF(A24="","",SUMIF(ABONOS!$B$2:$B$220,A24,ABONOS!$E$2:$E$220)) -> 0 | Q24: =IF(A24="","",K24-P24) -> 0 | R24: =IFERROR(IF(A24="","",P24/K24),"")
A25: V024 | B25: Ama | C25: L-024 | D25: 250 | P25: =IF(A25="","",SUMIF(ABONOS!$B$2:$B$220,A25,ABONOS!$E$2:$E$220)) -> 0 | Q25: =IF(A25="","",K25-P25) -> 0 | R25: =IFERROR(IF(A25="","",P25/K25),"")
A26: V025 | B26: Ama | C26: L-025 | D26: 250 | P26: =IF(A26="","",SUMIF(ABONOS!$B$2:$B$220,A26,ABONOS!$E$2:$E$220)) -> 0 | Q26: =IF(A26="","",K26-P26) -> 0 | R26: =IFERROR(IF(A26="","",P26/K26),"")
... A39: V038 | B39: Ama | C39: L-038 | D39: 500 | P39: =IF(A39="","",SUMIF(ABONOS!$B$2:$B$220,A39,ABONOS!$E$2:$E$220)) -> 0 | Q39: =IF(A39="","",K39-P39) -> 0 | R39: =IFERROR(IF(A39="","",P39/K39),"")
A40: V039 | B40: Ama | C40: L-039 | D40: 485 | E40: MANUEL BURBANO | F40: 1114829022 | J40: 46255 | K40: 95000000 | L40: 47500000 | P40: =IF(A40="","",SUMIF(ABONOS!$B$2:$B$220,A40,ABONOS!$E$2:$E$220)) -> 50000000 | Q40: =IF(A40="","",K40-P40) -> 45000000 | R40: =IFERROR(IF(A40="","",P40/K40),"") -> 0.52631579
A41: V040 | B41: Ama | C41: L-040 | D41: 500 | P41: =IF(A41="","",SUMIF(ABONOS!$B$2:$B$220,A41,ABONOS!$E$2:$E$220)) -> 0 | Q41: =IF(A41="","",K41-P41) -> 0 | R41: =IFERROR(IF(A41="","",P41/K41),"")
A42: V041 | B42: Ama | C42: L-041 | D42: 500 | E42: MARIA ISABEL SALAMANCA | F42: 1144069969 | J42: 46263 | P42: =IF(A42="","",SUMIF(ABONOS!$B$2:$B$220,A42,ABONOS!$E$2:$E$220)) -> 0 | Q42: =IF(A42="","",K42-P42) -> 0 | R42: =IFERROR(IF(A42="","",P42/K42),"")
A43: V042 | B43: Ama | C43: L-042 | D43: 500 | E43: PABLO PEREZ ROSERO | K43: 85000000 | L43: 42500000 | P43: =IF(A43="","",SUMIF(ABONOS!$B$2:$B$220,A43,ABONOS!$E$2:$E$220)) -> 50000000 | Q43: =IF(A43="","",K43-P43) -> 35000000 | R43: =IFERROR(IF(A43="","",P43/K43),"") -> 0.58823529
A44: V043 | B44: Ama | C44: L-043 | D44: 500 | P44: =IF(A44="","",SUMIF(ABONOS!$B$2:$B$220,A44,ABONOS!$E$2:$E$220)) -> 0 | Q44: =IF(A44="","",K44-P44) -> 0 | R44: =IFERROR(IF(A44="","",P44/K44),"")
A45: V044 | B45: Ama | C45: L-044 | D45: 500 | P45: =IF(A45="","",SUMIF(ABONOS!$B$2:$B$220,A45,ABONOS!$E$2:$E$220)) -> 0 | Q45: =IF(A45="","",K45-P45) -> 0 | R45: =IFERROR(IF(A45="","",P45/K45),"")
A46: V045 | B46: Ama | C46: L-045 | D46: 486 | E46: MANUEL BURBANO | F46: 1114829022 | J46: 46255 | K46: 95000000 | L46: 47500000 | P46: =IF(A46="","",SUMIF(ABONOS!$B$2:$B$220,A46,ABONOS!$E$2:$E$220)) -> 50000000 | Q46: =IF(A46="","",K46-P46) -> 45000000 | R46: =IFERROR(IF(A46="","",P46/K46),"") -> 0.52631579
A47: V046 | B47: Ama | C47: L-046 | D47: 500 | E47: PABLO PEREZ ROSERO | K47: 85000000 | L47: 42500000 | P47: =IF(A47="","",SUMIF(ABONOS!$B$2:$B$220,A47,ABONOS!$E$2:$E$220)) -> 50000000 | Q47: =IF(A47="","",K47-P47) -> 35000000 | R47: =IFERROR(IF(A47="","",P47/K47),"") -> 0.58823529
A48: V047 | B48: Ama | C48: L-047 | D48: 505 | E48: CLAUDIA FERNANDA INSUASTY ARCOS | F48: 1113626660 | G48: 3108303822 | H48: Claudiaarcos369@gmail.com | I48: CL 30 #30-77 | J48: 46238 | K48: 85000000 | L48: 42500000 | P48: =IF(A48="","",SUMIF(ABONOS!$B$2:$B$220,A48,ABONOS!$E$2:$E$220)) -> 75000000 | Q48: =IF(A48="","",K48-P48) -> 10000000 | R48: =IFERROR(IF(A48="","",P48/K48),"") -> 0.88235294
A49: V048 | B49: Ama | C49: L-048 | D49: 505 | E49: HAROL JAIME PEREZ ROSERO | F49: 14697341 | P49: =IF(A49="","",SUMIF(ABONOS!$B$2:$B$220,A49,ABONOS!$E$2:$E$220)) -> 0 | Q49: =IF(A49="","",K49-P49) -> 0 | R49: =IFERROR(IF(A49="","",P49/K49),"")
A50: V049 | B50: Ama | C50: L-049 | D50: 695 | P50: =IF(A50="","",SUMIF(ABONOS!$B$2:$B$220,A50,ABONOS!$E$2:$E$220)) -> 0 | Q50: =IF(A50="","",K50-P50) -> 0 | R50: =IFERROR(IF(A50="","",P50/K50),"")
A51: V050 | B51: Ama | C51: L-050 | D51: 408 | P51: =IF(A51="","",SUMIF(ABONOS!$B$2:$B$220,A51,ABONOS!$E$2:$E$220)) -> 0 | Q51: =IF(A51="","",K51-P51) -> 0 | R51: =IFERROR(IF(A51="","",P51/K51),"")
A52: V051 | B52: Ama | C52: L-051 | D52: 523 | P52: =IF(A52="","",SUMIF(ABONOS!$B$2:$B$220,A52,ABONOS!$E$2:$E$220)) -> 0 | Q52: =IF(A52="","",K52-P52) -> 0 | R52: =IFERROR(IF(A52="","",P52/K52),"")
...

Sheet ABONOS
A1: ID abono | B1: ID venta | C1: N° cuota aplicada | D1: Fecha abono | E1: Valor recibido | F1: Medio de pago | G1: Referencia | H1: Observaciones
A2: A0001 | B2: V076 | C2: 1 | D2: 46303 | E2: 30000000 | F2: Consignación | G2: 442774 | H2: DAVIVIENDA
A3: A0002 | B3: V076 | C3: 2 | D3: 46308 | E3: 30000000 | F3: Consignación | G3: 23381 | H3: DAVIVIENDA
A4: A0003 | B4: V008 | C4: 1 | E4: 45000000
A5: A0004 | B5: V003 | C5: 1 | E5: 30000000
A6: A0005 | B6: V004 | C6: 1 | E6: 30000000
A7: A0006 | B7: V052 | C7: 1 | E7: 30000000
A8: A0007 | B8: V006 | C8: 1 | D8: 46274 | E8: 18500000 | F8: Consignación | G8: 713582 | H8: DAVIVIENDA
A9: A0008 | B9: V007 | C9: 1 | D9: 46274 | E9: 18500000 | F9: Consignación | G9: 713582 | H9: DAVIVIENDA
A10: A0009 | B10: V042 | C10: 1 | E10: 50000000
A11: A0010 | B11: V046 | C11: 1 | E11: 50000000
A12: A0011 | B12: V039 | C12: 1 | D12: 46286 | E12: 50000000
A13: A0012 | B13: V045 | C13: 1 | D13: 46286 | E13: 50000000
A14: A0013 | B14: V047 | C14: 1 | E14: 75000000
A15: A0014 | B15: V054 | C15: 1 | E15: 75000000
A16: A0015 | B16: V055 | C16: 1 | E16: 75000000
A17: A0016 | B17: V059 | C17: 1 | E17: 75000000
A18: A0017 | B18: V074 | C18: 1 | D18: 46296 | E18: 62000000 | F18: Consignación | H18: DAVIVIENDA
A19: A0018 | B19: V077 | C19: 1 | D19: 46296 | E19: 62000000 | F19: Consignación | H19: DAVIVIENDA
A20: A0019
A21: A0020
A22: A0021
A23: A0022
A24: A0023
A25: A0024
A26: A0025
A27: A0026
A28: A0027
A29: A0028
A30: A0029
A31: A0030
... A45: A0044

Sheet PROYECTOS
A1: ID proyecto | B1: Proyecto | C1: Municipio | D1: Lotes planeados
A2: Ama | B2: Amaranta | C2: El Cerrito | D2: 100
A3: PR02 | B3: Los Almendros | C3: Palmira | D3: 75
A4: PR03 | B4: Altos del Valle | C4: Ginebra | D4: 48

Sheet COMISIONES
A1: ID comisión | B1: ID venta | C1: ¿Aplica? | D1: Comisionista | E1: % comisión | F1: Fecha_comision | G1: Metodo_pago | H1: Valor comisión | I1: Pagado | J1: Saldo comisión
A2: CM001 | H2: =IF(B2="","",IF(C2="Sí",IFERROR(INDEX(VENTAS!$K$2:$K$100,MATCH(B2,VENTAS!$A$2:$A$100,0))*E2,0),0)) | J2: =IF(A2="","",H2-I2) -> #VALUE!
A3: CM002 | H3: =IF(B3="","",IF(C3="Sí",IFERROR(INDEX(VENTAS!$K$2:$K$100,MATCH(B3,VENTAS!$A$2:$A$100,0))*E3,0),0)) | J3: =IF(A3="","",H3-I3) -> #VALUE!
A4: CM003 | H4: =IF(B4="","",IF(C4="Sí",IFERROR(INDEX(VENTAS!$K$2:$K$100,MATCH(B4,VENTAS!$A$2:$A$100,0))*E4,0),0)) | J4: =IF(A4="","",H4-I4) -> #VALUE!
A5: CM004 | H5: =IF(B5="","",IF(C5="Sí",IFERROR(INDEX(VENTAS!$K$2:$K$100,MATCH(B5,VENTAS!$A$2:$A$100,0))*E5,0),0)) | J5: =IF(A5="","",H5-I5) -> #VALUE!
A6: CM005 | H6: =IF(B6="","",IF(C6="Sí",IFERROR(INDEX(VENTAS!$K$2:$K$100,MATCH(B6,VENTAS!$A$2:$A$100,0))*E6,0),0)) | J6: =IF(A6="","",H6-I6) -> #VALUE!
A7: CM006 | H7: =IF(B7="","",IF(C7="Sí",IFERROR(INDEX(VENTAS!$K$2:$K$100,MATCH(B7,VENTAS!$A$2:$A$100,0))*E7,0),0)) | J7: =IF(A7="","",H7-I7) -> #VALUE!
A8: CM007 | H8: =IF(B8="","",IF(C8="Sí",IFERROR(INDEX(VENTAS!$K$2:$K$100,MATCH(B8,VENTAS!$A$2:$A$100,0))*E8,0),0)) | J8: =IF(A8="","",H8-I8) -> #VALUE!
A9: CM008 | H9: =IF(B9="","",IF(C9="Sí",IFERROR(INDEX(VENTAS!$K$2:$K$100,MATCH(B9,VENTAS!$A$2:$A$100,0))*E9,0),0)) | J9: =IF(A9="","",H9-I9) -> #VALUE!
A10: CM009 | H10: =IF(B10="","",IF(C10="Sí",IFERROR(INDEX(VENTAS!$K$2:$K$100,MATCH(B10,VENTAS!$A$2:$A$100,0))*E10,0),0)) | J10: =IF(A10="","",H10-I10) -> #VALUE!
A11: CM010 | H11: =IF(B11="","",IF(C11="Sí",IFERROR(INDEX(VENTAS!$K$2:$K$100,MATCH(B11,VENTAS!$A$2:$A$100,0))*E11,0),0)) | J11: =IF(A11="","",H11-I11) -> #VALUE!
A12: CM011 | H12: =IF(B12="","",IF(C12="Sí",IFERROR(INDEX(VENTAS!$K$2:$K$100,MATCH(B12,VENTAS!$A$2:$A$100,0))*E12,0),0)) | J12: =IF(A12="","",H12-I12) -> #VALUE!
A13: CM012 | H13: =IF(B13="","",IF(C13="Sí",IFERROR(INDEX(VENTAS!$K$2:$K$100,MATCH(B13,VENTAS!$A$2:$A$100,0))*E13,0),0)) | J13: =IF(A13="","",H13-I13) -> #VALUE!
A14: CM013 | H14: =IF(B14="","",IF(C14="Sí",IFERROR(INDEX(VENTAS!$K$2:$K$100,MATCH(B14,VENTAS!$A$2:$A$100,0))*E14,0),0)) | J14: =IF(A14="","",H14-I14) -> #VALUE!
H15: =IF(B15="","",IF(C15="Sí",IFERROR(INDEX(VENTAS!$K$2:$K$100,MATCH(B15,VENTAS!$A$2:$A$100,0))*E15,0),0)) | I15: =IF(A15="","",SUMIF(#REF!,A15,#REF!)) | J15: =IF(A15="","",H15-I15)
H16: =IF(B16="","",IF(C16="Sí",IFERROR(INDEX(VENTAS!$K$2:$K$100,MATCH(B16,VENTAS!$A$2:$A$100,0))*E16,0),0)) | I16: =IF(A16="","",SUMIF(#REF!,A16,#REF!)) | J16: =IF(A16="","",H16-I16)
H17: =IF(B17="","",IF(C17="Sí",IFERROR(INDEX(VENTAS!$K$2:$K$100,MATCH(B17,VENTAS!$A$2:$A$100,0))*E17,0),0)) | I17: =IF(A17="","",SUMIF(#REF!,A17,#REF!)) | J17: =IF(A17="","",H17-I17)
H18: =IF(B18="","",IF(C18="Sí",IFERROR(INDEX(VENTAS!$K$2:$K$100,MATCH(B18,VENTAS!$A$2:$A$100,0))*E18,0),0)) | I18: =IF(A18="","",SUMIF(#REF!,A18,#REF!)) | J18: =IF(A18="","",H18-I18)
H19: =IF(B19="","",IF(C19="Sí",IFERROR(INDEX(VENTAS!$K$2:$K$100,MATCH(B19,VENTAS!$A$2:$A$100,0))*E19,0),0)) | I19: =IF(A19="","",SUMIF(#REF!,A19,#REF!)) | J19: =IF(A19="","",H19-I19)
H20: =IF(B20="","",IF(C20="Sí",IFERROR(INDEX(VENTAS!$K$2:$K$100,MATCH(B20,VENTAS!$A$2:$A$100,0))*E20,0),0)) | I20: =IF(A20="","",SUMIF(#REF!,A20,#REF!)) | J20: =IF(A20="","",H20-I20)
H21: =IF(B21="","",IF(C21="Sí",IFERROR(INDEX(VENTAS!$K$2:$K$100,MATCH(B21,VENTAS!$A$2:$A$100,0))*E21,0),0)) | I21: =IF(A21="","",SUMIF(#REF!,A21,#REF!)) | J21: =IF(A21="","",H21-I21)
H22: =IF(B22="","",IF(C22="Sí",IFERROR(INDEX(VENTAS!$K$2:$K$100,MATCH(B22,VENTAS!$A$2:$A$100,0))*E22,0),0)) | I22: =IF(A22="","",SUMIF(#REF!,A22,#REF!)) | J22: =IF(A22="","",H22-I22)
H23: =IF(B23="","",IF(C23="Sí",IFERROR(INDEX(VENTAS!$K$2:$K$100,MATCH(B23,VENTAS!$A$2:$A$100,0))*E23,0),0)) | I23: =IF(A23="","",SUMIF(#REF!,A23,#REF!)) | J23: =IF(A23="","",H23-I23)
H24: =IF(B24="","",IF(C24="Sí",IFERROR(INDEX(VENTAS!$K$2:$K$100,MATCH(B24,VENTAS!$A$2:$A$100,0))*E24,0),0)) | I24: =IF(A24="","",SUMIF(#REF!,A24,#REF!)) | J24: =IF(A24="","",H24-I24)
H25: =IF(B25="","",IF(C25="Sí",IFERROR(INDEX(VENTAS!$K$2:$K$100,MATCH(B25,VENTAS!$A$2:$A$100,0))*E25,0),0)) | I25: =IF(A25="","",SUMIF(#REF!,A25,#REF!)) | J25: =IF(A25="","",H25-I25)
H26: =IF(B26="","",IF(C26="Sí",IFERROR(INDEX(VENTAS!$K$2:$K$100,MATCH(B26,VENTAS!$A$2:$A$100,0))*E26,0),0)) | I26: =IF(A26="","",SUMIF(#REF!,A26,#REF!)) | J26: =IF(A26="","",H26-I26)
... H200: =IF(B200="","",IF(C200="Sí",IFERROR(INDEX(VENTAS!$K$2:$K$100,MATCH(B200,VENTAS!$A$2:$A$100,0))*E200,0),0)) | I200: =IF(A200="","",SUMIF(#REF!,A200,#REF!)) | J200: =IF(A200="","",H200-I200)

Sheet GUIA
A1: GUÍA DE USO | B1: ARCHIVO DEMOSTRATIVO · DATOS SIMULADOS
A2: 1 | B2: En PROYECTOS registre el catálogo de proyectos y sus IDs. | D2: Banco | E2: metodos
A3: 2 | B3: En VENTAS registre cada negocio con ID único, precio y cuota inicial pactada. | D3: Davivienda | E3: Efectivo
A4: 3 | B4: En CUOTAS registre cada obligación con número, fecha y valor pactado. | D4: Bancolombia | E4: Consignacion
A5: 4 | B5: En ABONOS registre CADA pago real y el número de cuota al que se aplica. | E5: Transferencia
A6: 5 | B6: Si un pago cubre varias cuotas, divídalo en varios registros de ABONOS con referencias compartidas.
A7: 6 | B7: El valor de cuota inicial pactada NO suma como recaudo hasta registrarse en ABONOS.
A8: 7 | B8: En COMISIONES registre el porcentaje y en PAGOS_COMISION los pagos efectuados.
A9: 8 | B9: En ESTADO_CUENTA cambie la celda B4 por un ID de venta para consultar el cliente.
A10: 9 | B10: El TABLERO resume cartera, recaudo y comisiones. Las fórmulas se actualizan en Excel.
A11: 10 | B11: El estado de mora se determina con la fecha actual del equipo.
A12: NOTA | B12: Los datos son ficticios y solo sirven como ejemplo. Reemplácelos antes de usar el archivo.
A13: CAPACIDAD | B13: Las fórmulas están preparadas hasta la fila 200 (220 en abonos y cuotas).
A14: IMPORTANTE | B14: Los abonos se aplican a cuotas por ID venta y número de cuota; evite duplicar registros.
B19: Ba
